Workbook

Sheet Time Table
G1: =sumif($F$26:$F$40,F1,$B$26:$B$40) -> 0
F2: {=UNIQUE(F26:F40)} -> health | G2: =sumif($F$26:$F$40,F2,$B$26:$B$40) -> 10.5
F3: fitness | G3: =sumif($F$26:$F$40,F3,$B$26:$B$40) -> 1.5
F4: hygene | G4: =sumif($F$26:$F$40,F4,$B$26:$B$40) -> 1.5
A5: =sum(A8:A936) -> 0 | B5: =sum(B8:B936) -> 26 | F5: wealth | G5: =sumif($F$26:$F$40,F5,$B$26:$B$40) -> 11
F6: rest | G6: =sumif($F$26:$F$40,F6,$B$26:$B$40) -> 1.5
G7: =sumif($F$26:$F$40,F7,$B$26:$B$40) -> 0
R8: =SUM(R10:R936) -> 3.5 | Z8: Available Time / Week | AA8: =7*24 -> 168
A9: Monthly Income | B9: Weekly Income | C9: Column 1 | D9: Column 2 | E9: Monday | F9: Column 12 | G9: Column 13 | H9: Tuesday | I9: Wednesday | J9: Thursday | K9: Friday | L9: Saturday | M9: Sunday | R9: HRS | S9: COUNT | AA9: =sum(J8:J936) -> 0 | AN9: =sum(AN10:AN18) -> 13787
C10: 0.20833333 | D10: 0.25 | E10: wakeup and pranayama | H10: wakeup and pranayama | I10: wakeup and pranayama | J10: wakeup and pranayama | K10: wakeup and pranayama | L10: wakeup and pranayama | M10: wakeup and pranayama | R10: =S10/2 -> 0 | S10: =COUNTIF(Table2[[Monday]:[Sunday]],T10) -> 0 | T10: BRUSH & BATH | Y10: Daily | Z10: Repeats/Week | AA10: Weekly | AN10: 5
C11: 0.25 | D11: 0.29166667 | E11: walking | H11: walking | I11: walking | J11: walking | K11: walking | L11: walking | M11: walking | R11: =S11/2 -> 0 | S11: =COUNTIF(Table2[[Monday]:[Sunday]],T11) -> 0 | T11: TRIP TO STADIUM | V11: 0.22916667 | W11: 0.33333333 | X11: Badminton, Brush, Bath, Temple, Breakfast | Y11: 2.5 | Z11: 7 | AA11: =Y11*Z11 -> 17.5 | AN11: 801
C12: 0.29166667 | D12: 0.3125 | E12: brush and bath | H12: brush and bath | I12: brush and bath | J12: brush and bath | K12: brush and bath | L12: brush and bath | M12: brush and bath | R12: =S12/2 -> 0 | S12: =COUNTIF(Table2[[Monday]:[Sunday]],T12) -> 0 | T12: BADMINTON | V12: 0.33333333 | W12: 0.41666667 | X12: Freelancing - Ishika | Y12: 2 | Z12: 5 | AA12: =Y12*Z12 -> 10 | AN12: 1588
C13: 0.3125 | D13: 0.39583333 | E13: ishika freelance support | H13: ishika freelance support | I13: ishika freelance support | J13: ishika freelance support | K13: ishika freelance support | R13: =S13/2 -> 0 | S13: =COUNTIF(Table2[[Monday]:[Sunday]],T13) -> 0 | T13: TRIP TO TEMPLE | V13: 0.41666667 | W13: 0.625 | X13: Trading - Akshay | Y13: 3 | Z13: 5 | AA13: =Y13*Z13 -> 15 | AN13: 1612
C14: 0.39583333 | D14: 0.4375 | E14: suryanamaskar and breakfast with medicine | H14: suryanamaskar and breakfast with medicine | I14: suryanamaskar and breakfast with medicine | J14: suryanamaskar and breakfast with medicine | K14: suryanamaskar and breakfast with medicine | L14: suryanamaskar and breakfast with medicine | M14: suryanamaskar and breakfast with medicine | R14: =S14/2 -> 0 | S14: =COUNTIF(Table2[[Monday]:[Sunday]],T14) -> 0 | T14: BREAKFAST | V14: 0.41666667 | W14: 0.625 | X14: Youtube - Intellect Reef | Y14: 3 | Z14: 1 | AA14: =Y14*Z14 -> 3 | AN14: 18
C15: 0.4375 | D15: 0.5625 | E15: office work 3 hrs | H15: office work 3 hrs | I15: office work 3 hrs | J15: office work 3 hrs | K15: office work 3 hrs | R15: =S15/2 -> 0 | S15: =COUNTIF(Table2[[Monday]:[Sunday]],T15) -> 0 | T15: FREELANCING - ISHIKA | V15: 0.41666667 | W15: 0.625 | X15: Youtube - Coding Reef | Y15: 3 | Z15: 1 | AA15: =Y15*Z15 -> 3 | AN15: 1712
C16: 0.5625 | D16: 0.60416667 | E16: suryanamaskar and lunch | H16: suryanamaskar and lunch | I16: suryanamaskar and lunch | J16: suryanamaskar and lunch | K16: suryanamaskar and lunch | L16: suryanamaskar and lunch | M16: suryanamaskar and lunch | R16: =S16/2 -> 0 | S16: =COUNTIF(Table2[[Monday]:[Sunday]],T16) -> 0 | T16: OFFICE | V16: 0.41666667 | W16: 0.625 | X16: Book Publishing | Y16: 4 | Z16: 1 | AA16: =Y16*Z16 -> 4 | AN16: 1674
C17: 0.60416667 | D17: 0.72916667 | E17: office work 3 hrs | H17: office work 3 hrs | I17: office work 3 hrs | J17: office work 3 hrs | K17: office work 3 hrs | R17: =S17/2 -> 0 | S17: =COUNTIF(Table2[[Monday]:[Sunday]],T17) -> 0 | T17: TRADING - AKSHAY | V17: 0.625 | W17: 0.70833333 | X17: Sleep | Y17: 2 | Z17: 7 | AA17: =Y17*Z17 -> 14 | AN17: 3372
C18: 0.72916667 | D18: 0.77083333 | E18: suryanamaskar and dinner with medicine | H18: suryanamaskar and dinner with medicine | I18: suryanamaskar and dinner with medicine | J18: suryanamaskar and dinner with medicine | K18: suryanamaskar and dinner with medicine | L18: suryanamaskar and dinner with medicine | M18: suryanamaskar and dinner with medicine | R18: =S18/2 -> 3.5 | S18: =COUNTIF(Table2[[Monday]:[Sunday]],T18) -> 7 | T18: SLEEP | V18: 0.70833333 | W18: 0.77083333 | X18: Freelancing - Soujanya | Y18: 1.5 | Z18: 5 | AA18: =Y18*Z18 -> 7.5 | AN18: 3005
C19: 0.77083333 | D19: 0.79166667 | E19: walking | H19: walking | I19: walking | J19: walking | K19: walking | L19: walking | M19: walking | R19: =S19/2 -> 0 | S19: =COUNTIF(Table2[[Monday]:[Sunday]],T19) -> 0 | T19: FREELANCING - SOUJANYA | V19: 0.77083333 | W19: 0 | X19: Job Apptware Solutiona | Y19: 5.5 | Z19: 5 | AA19: =Y19*Z19 -> 27.5
C20: 0.79166667 | D20: 0.85416667 | E20: mits soujanya freelance support | H20: mits soujanya freelance support | I20: mits soujanya freelance support | J20: mits soujanya freelance support | K20: mits soujanya freelance support | R20: =S20/2 -> 0 | S20: =COUNTIF(Table2[[Monday]:[Sunday]],T20) -> 0 | T20: YOUTUBE - INTELLECT REEF | V20: 0 | W20: 0.20833333 | X20: Sleep | Y20: 5 | Z20: 7 | AA20: =Y20*Z20 -> 35
C21: 0.85416667 | D21: 0.9375 | E21: office work 2 hrs | H21: office work 2 hrs | I21: office work 2 hrs | J21: office work 2 hrs | K21: office work 2 hrs | R21: =S21/2 -> 0 | S21: =COUNTIF(Table2[[Monday]:[Sunday]],T21) -> 0 | T21: YOUTUBE - CODING REEF | X21: App Development | Y21: 8 | Z21: 1 | AA21: =Y21*Z21 -> 8
C22: 0.9375 | D22: 0.95833333 | E22: evening rituals and sleep | H22: evening rituals and sleep | I22: evening rituals and sleep | J22: evening rituals and sleep | K22: evening rituals and sleep | L22: evening rituals and sleep | M22: evening rituals and sleep | R22: =S22/2 -> 0 | S22: =COUNTIF(Table2[[Monday]:[Sunday]],T22) -> 0 | T22: App Development | X22: Professional Development | Y22: 8 | Z22: 1 | AA22: =Y22*Z22 -> 8
R23: =S23/2 -> 0 | S23: =COUNTIF(Table2[[Monday]:[Sunday]],T23) -> 0 | T23: LAUNDARY
R24: =S24/2 -> 0 | S24: =COUNTIF(Table2[[Monday]:[Sunday]],T24) -> 0 | T24: Professional Development
R25: =S25/2 -> 0 | S25: =COUNTIF(Table2[[Monday]:[Sunday]],T25) -> 0 | T25: Book Publishing
B26: 1 | C26: 0.20833333 | D26: 0.25 | E26: wakeup and pranayama | F26: health | H26: wakeup and pranayama | I26: wakeup and pranayama | J26: wakeup and pranayama | K26: wakeup and pranayama | L26: wakeup and pranayama | M26: wakeup and pranayama
B27: 1 | C27: 0.25 | D27: 0.29166667 | E27: walking | F27: fitness | H27: walking | I27: walking | J27: walking | K27: walking | L27: walking | M27: walking
B28: 1.5 | C28: 0.29166667 | D28: 0.3125 | E28: brush and bath | F28: hygene | H28: brush and bath | I28: brush and bath | J28: brush and bath | K28: brush and bath | L28: brush and bath | M28: brush and bath
B29: 2 | C29: 0.3125 | D29: 0.39583333 | E29: ishika freelance support 2 hrs office | F29: wealth | H29: ishika freelance support 2 hrs office | I29: ishika freelance support 2 hrs office | J29: ishika freelance support 2 hrs office | K29: ishika freelance support 2 hrs office
B30: 1 | C30: 0.39583333 | D30: 0.4375 | E30: suryanamaskar and breakfast with medicine | F30: health | H30: suryanamaskar and breakfast with medicine | I30: suryanamaskar and breakfast with medicine | J30: suryanamaskar and breakfast with medicine | K30: suryanamaskar and breakfast with medicine | L30: suryanamaskar and breakfast with medicine | M30: suryanamaskar and breakfast with medicine
B31: 3 | C31: 0.4375 | D31: 0.5625 | E31: office work 3 hrs | F31: wealth | H31: office work 3 hrs | I31: office work 3 hrs | J31: office work 3 hrs | K31: office work 3 hrs
B32: 1 | C32: 0.5625 | D32: 0.60416667 | E32: suryanamaskar and lunch | F32: health | H32: suryanamaskar and lunch | I32: suryanamaskar and lunch | J32: suryanamaskar and lunch | K32: suryanamaskar and lunch | L32: suryanamaskar and lunch | M32: suryanamaskar and lunch
B33: 2 | C33: 0.60416667 | D33: 0.6875 | E33: office work 2 hrs | F33: wealth | H33: office work 2 hrs | I33: office work 2 hrs | J33: office work 2 hrs | K33: office work 2 hrs
B34: 1.5 | C34: 0.6875 | D34: 0.70833333 | E34: rest | F34: rest | H34: rest | I34: rest | J34: rest | K34: rest | L34: rest | M34: rest
B35: 1.5 | C35: 0.70833333 | D35: 0.77083333 | E35: mits soujanya freelance support 1.5 hrs office | F35: wealth | H35: mits soujanya freelance support 1.5 hrs office | I35: mits soujanya freelance support 1.5 hrs office | J35: mits soujanya freelance support 1.5 hrs office | K35: mits soujanya freelance support 1.5 hrs office
B36: 1 | C36: 0.77083333 | D36: 0.8125 | E36: suryanamaskar and dinner | F36: health | H36: suryanamaskar and dinner | I36: suryanamaskar and dinner | J36: suryanamaskar and dinner | K36: suryanamaskar and dinner | L36: suryanamaskar and dinner | M36: suryanamaskar and dinner
B37: 0.5 | C37: 0.8125 | D37: 0.83333333 | E37: walking | F37: fitness | H37: walking | I37: walking | J37: walking | K37: walking | L37: walking | M37: walking
B38: 2.5 | C38: 0.83333333 | D38: 0.9375 | E38: office work 2.5 hrs | F38: wealth | H38: office work 2.5 hrs | I38: office work 2.5 hrs | J38: office work 2.5 hrs | K38: office work 2.5 hrs
B39: 0.5 | C39: 0.9375 | D39: 0.95833333 | E39: evening rituals and sleep | F39: health | H39: evening rituals and sleep | I39: evening rituals and sleep | J39: evening rituals and sleep | K39: evening rituals and sleep | L39: evening rituals and sleep | M39: evening rituals and sleep
B40: 6 | C40: 0.95833333 | D40: 0.20833333 | E40: sleep | F40: health | H40: sleep | I40: sleep | J40: sleep | K40: sleep | L40: sleep | M40: sleep

Sheet Copy of Time Table
A5: =sum(A8:A935) -> 0 | B5: =sum(B8:B935) -> 0
P8: =SUM(P10:P935) -> 165 | X8: Available Time / Week | Y8: =7*24 -> 168
A9: Monthly Income | B9: Weekly Income | C9: Column 1 | D9: Column 2 | E9: Monday | F9: Tuesday | G9: Wednesday | H9: Thursday | I9: Friday | J9: Saturday | K9: Sunday | P9: HRS | Q9: COUNT | Y9: =sum(H8:H935) -> 0 | AL9: =sum(AL10:AL18) -> 13787
C10: 1.2083333 | D10: 1.2291667 | E10: BRUSH & BATH | F10: BRUSH & BATH | G10: BRUSH & BATH | H10: BRUSH & BATH | I10: BRUSH & BATH | J10: BRUSH & BATH | K10: BRUSH & BATH | P10: =Q10/2 -> 3.5 | Q10: =COUNTIF(Table2_2[[Monday]:[Sunday]],R10) -> 7 | R10: BRUSH & BATH | W10: Daily | X10: Repeats/Week | Y10: Weekly | AL10: 5
C11: 1.2291667 | D11: 1.25 | E11: TRIP TO STADIUM | F11: TRIP TO STADIUM | G11: TRIP TO STADIUM | H11: TRIP TO STADIUM | I11: TRIP TO STADIUM | J11: TRIP TO STADIUM | K11: TRIP TO STADIUM | P11: =Q11/2 -> 3.5 | Q11: =COUNTIF(Table2_2[[Monday]:[Sunday]],R11) -> 7 | R11: TRIP TO STADIUM | T11: 0.22916667 | U11: 0.33333333 | V11: Badminton, Brush, Bath, Temple, Breakfast | W11: 2.5 | X11: 7 | Y11: =W11*X11 -> 17.5 | AL11: 801
C12: 0.25 | D12: 0.27083333 | E12: BADMINTON | F12: BADMINTON | G12: BADMINTON | H12: BADMINTON | I12: BADMINTON | J12: BADMINTON | K12: BADMINTON | P12: =Q12/2 -> 7 | Q12: =COUNTIF(Table2_2[[Monday]:[Sunday]],R12) -> 14 | R12: BADMINTON | T12: 0.33333333 | U12: 0.41666667 | V12: Freelancing - Ishika | W12: 2 | X12: 5 | Y12: =W12*X12 -> 10 | AL12: 1588
C13: 0.27083333 | D13: 0.29166667 | E13: BADMINTON | F13: BADMINTON | G13: BADMINTON | H13: BADMINTON | I13: BADMINTON | J13: BADMINTON | K13: BADMINTON | P13: =Q13/2 -> 3.5 | Q13: =COUNTIF(Table2_2[[Monday]:[Sunday]],R13) -> 7 | R13: TRIP TO TEMPLE | T13: 0.41666667 | U13: 0.625 | V13: Trading - Akshay | W13: 3 | X13: 5 | Y13: =W13*X13 -> 15 | AL13: 1612
C14: 0.29166667 | D14: 0.3125 | E14: TRIP TO TEMPLE | F14: TRIP TO TEMPLE | G14: TRIP TO TEMPLE | H14: TRIP TO TEMPLE | I14: TRIP TO TEMPLE | J14: TRIP TO TEMPLE | K14: TRIP TO TEMPLE | P14: =Q14/2 -> 3.5 | Q14: =COUNTIF(Table2_2[[Monday]:[Sunday]],R14) -> 7 | R14: BREAKFAST | T14: 0.41666667 | U14: 0.625 | V14: Youtube - Intellect Reef | W14: 3 | X14: 1 | Y14: =W14*X14 -> 3 | AL14: 18
C15: 0.3125 | D15: 0.33333333 | E15: BREAKFAST | F15: BREAKFAST | G15: BREAKFAST | H15: BREAKFAST | I15: BREAKFAST | J15: BREAKFAST | K15: BREAKFAST | P15: =Q15/2 -> 10 | Q15: =COUNTIF(Table2_2[[Monday]:[Sunday]],R15) -> 20 | R15: FREELANCING - ISHIKA | T15: 0.41666667 | U15: 0.625 | V15: Youtube - Coding Reef | W15: 3 | X15: 1 | Y15: =W15*X15 -> 3 | AL15: 1712
C16: 0.33333333 | D16: 0.35416667 | E16: FREELANCING - ISHIKA | F16: FREELANCING - ISHIKA | G16: FREELANCING - ISHIKA | H16: FREELANCING - ISHIKA | I16: FREELANCING - ISHIKA | J16: YOUTUBE - INTELLECT REEF | K16: YOUTUBE - CODING REEF | P16: =Q16/2 -> 40 | Q16: =COUNTIF(Table2_2[[Monday]:[Sunday]],R16) -> 80 | R16: OFFICE | T16: 0.41666667 | U16: 0.625 | V16: Book Publishing | W16: 4 | X16: 1 | Y16: =W16*X16 -> 4 | AL16: 1674
C17: 0.35416667 | D17: 0.375 | E17: FREELANCING - ISHIKA | F17: FREELANCING - ISHIKA | G17: FREELANCING - ISHIKA | H17: FREELANCING - ISHIKA | I17: FREELANCING - ISHIKA | J17: YOUTUBE - INTELLECT REEF | K17: YOUTUBE - CODING REEF | P17: =Q17/2 -> 17.5 | Q17: =COUNTIF(Table2_2[[Monday]:[Sunday]],R17) -> 35 | R17: TRADING - AKSHAY | T17: 0.625 | U17: 0.70833333 | V17: Sleep | W17: 2 | X17: 7 | Y17: =W17*X17 -> 14 | AL17: 3372
C18: 0.375 | D18: 0.39583333 | E18: FREELANCING - ISHIKA | F18: FREELANCING - ISHIKA | G18: FREELANCING - ISHIKA | H18: FREELANCING - ISHIKA | I18: FREELANCING - ISHIKA | J18: YOUTUBE - INTELLECT REEF | K18: YOUTUBE - CODING REEF | P18: =Q18/2 -> 42 | Q18: =COUNTIF(Table2_2[[Monday]:[Sunday]],R18) -> 84 | R18: SLEEP | T18: 0.70833333 | U18: 0.77083333 | V18: Freelancing - Soujanya | W18: 1.5 | X18: 5 | Y18: =W18*X18 -> 7.5 | AL18: 3005
C19: 0.39583333 | D19: 0.41666667 | E19: FREELANCING - ISHIKA | F19: FREELANCING - ISHIKA | G19: FREELANCING - ISHIKA | H19: FREELANCING - ISHIKA | I19: FREELANCING - ISHIKA | J19: YOUTUBE - INTELLECT REEF | K19: YOUTUBE - CODING REEF | P19: =Q19/2 -> 7.5 | Q19: =COUNTIF(Table2_2[[Monday]:[Sunday]],R19) -> 15 | R19: FREELANCING - SOUJANYA | T19: 0.77083333 | U19: 0 | V19: Job Apptware Solutiona | W19: 5.5 | X19: 5 | Y19: =W19*X19 -> 27.5
C20: 0.41666667 | D20: 0.4375 | E20: OFFICE | F20: OFFICE | G20: OFFICE | H20: OFFICE | I20: OFFICE | J20: LAUNDARY | K20: LAUNDARY | P20: =Q20/2 -> 3 | Q20: =COUNTIF(Table2_2[[Monday]:[Sunday]],R20) -> 6 | R20: YOUTUBE - INTELLECT REEF | T20: 0 | U20: 0.20833333 | V20: Sleep | W20: 5 | X20: 7 | Y20: =W20*X20 -> 35
C21: 0.4375 | D21: 0.45833333 | E21: TRADING - AKSHAY | F21: TRADING - AKSHAY | G21: TRADING - AKSHAY | H21: TRADING - AKSHAY | I21: TRADING - AKSHAY | J21: YOUTUBE - INTELLECT REEF | K21: YOUTUBE - CODING REEF | P21: =Q21/2 -> 4 | Q21: =COUNTIF(Table2_2[[Monday]:[Sunday]],R21) -> 8 | R21: YOUTUBE - CODING REEF | V21: App Development | W21: 8 | X21: 1 | Y21: =W21*X21 -> 8
C22: 0.45833333 | D22: 0.47916667 | E22: TRADING - AKSHAY | F22: TRADING - AKSHAY | G22: TRADING - AKSHAY | H22: TRADING - AKSHAY | I22: TRADING - AKSHAY | J22: YOUTUBE - INTELLECT REEF | K22: YOUTUBE - CODING REEF | P22: =Q22/2 -> 5 | Q22: =COUNTIF(Table2_2[[Monday]:[Sunday]],R22) -> 10 | R22: App Development | V22: Professional Development | W22: 8 | X22: 1 | Y22: =W22*X22 -> 8
C23: 0.47916667 | D23: 0.5 | E23: TRADING - AKSHAY | F23: TRADING - AKSHAY | G23: TRADING - AKSHAY | H23: TRADING - AKSHAY | I23: TRADING - AKSHAY | J23: App Development | K23: YOUTUBE - CODING REEF | P23: =Q23/2 -> 3 | Q23: =COUNTIF(Table2_2[[Monday]:[Sunday]],R23) -> 6 | R23: LAUNDARY
C24: 0.5 | D24: 0.52083333 | E24: TRADING - AKSHAY | F24: TRADING - AKSHAY | G24: TRADING - AKSHAY | H24: TRADING - AKSHAY | I24: TRADING - AKSHAY | J24: App Development | K24: YOUTUBE - CODING REEF | P24: =Q24/2 -> 6 | Q24: =COUNTIF(Table2_2[[Monday]:[Sunday]],R24) -> 12 | R24: Professional Development
C25: 0.52083333 | D25: 0.54166667 | E25: OFFICE | F25: OFFICE | G25: OFFICE | H25: OFFICE | I25: OFFICE | J25: LAUNDARY | K25: LAUNDARY | P25: =Q25/2 -> 6 | Q25: =COUNTIF(Table2_2[[Monday]:[Sunday]],R25) -> 12 | R25: Book Publishing
C26: 0.54166667 | D26: 0.5625 | E26: OFFICE | F26: OFFICE | G26: OFFICE | H26: OFFICE | I26: OFFICE | J26: App Development | K26: App Development
C27: 0.5625 | D27: 0.58333333 | E27: TRADING - AKSHAY | F27: TRADING - AKSHAY | G27: TRADING - AKSHAY | H27: TRADING - AKSHAY | I27: TRADING - AKSHAY | J27: App Development | K27: App Development
C28: 0.58333333 | D28: 0.60416667 | E28: TRADING - AKSHAY | F28: TRADING - AKSHAY | G28: TRADING - AKSHAY | H28: TRADING - AKSHAY | I28: TRADING - AKSHAY | J28: App Development | K28: App Development
C29: 0.60416667 | D29: 0.625 | E29: TRADING - AKSHAY | F29: TRADING - AKSHAY | G29: TRADING - AKSHAY | H29: TRADING - AKSHAY | I29: TRADING - AKSHAY | J29: App Development | K29: App Development
C30: 0.625 | D30: 0.64583333 | E30: SLEEP | F30: SLEEP | G30: SLEEP | H30: SLEEP | I30: SLEEP | J30: SLEEP | K30: SLEEP
C31: 0.64583333 | D31: 0.66666667 | E31: SLEEP | F31: SLEEP | G31: SLEEP | H31: SLEEP | I31: SLEEP | J31: SLEEP | K31: SLEEP
C32: 0.66666667 | D32: 0.6875 | E32: SLEEP | F32: SLEEP | G32: SLEEP | H32: SLEEP | I32: SLEEP | J32: SLEEP | K32: SLEEP
C33: 0.6875 | D33: 0.70833333 | E33: SLEEP | F33: SLEEP | G33: SLEEP | H33: SLEEP | I33: SLEEP | J33: SLEEP | K33: SLEEP
C34: 0.70833333 | D34: 0.72916667 | E34: FREELANCING - SOUJANYA | F34: FREELANCING - SOUJANYA | G34: FREELANCING - SOUJANYA | H34: FREELANCING - SOUJANYA | I34: FREELANCING - SOUJANYA | J34: Professional Development | K34: Professional Development
C35: 0.72916667 | D35: 0.75 | E35: FREELANCING - SOUJANYA | F35: FREELANCING - SOUJANYA | G35: FREELANCING - SOUJANYA | H35: FREELANCING - SOUJANYA | I35: FREELANCING - SOUJANYA | J35: Professional Development | K35: Professional Development
C36: 0.75 | D36: 0.77083333 | E36: FREELANCING - SOUJANYA | F36: FREELANCING - SOUJANYA | G36: FREELANCING - SOUJANYA | H36: FREELANCING - SOUJANYA | I36: FREELANCING - SOUJANYA | J36: Professional Development | K36: Professional Development
C37: 0.77083333 | D37: 0.79166667 | E37: OFFICE | F37: OFFICE | G37: OFFICE | H37: OFFICE | I37: OFFICE | J37: Professional Development | K37: Professional Development
C38: 0.79166667 | D38: 0.8125 | E38: OFFICE | F38: OFFICE | G38: OFFICE | H38: OFFICE | I38: OFFICE
C39: 0.8125 | D39: 0.83333333 | E39: OFFICE | F39: OFFICE | G39: OFFICE | H39: OFFICE | I39: OFFICE | J39: Professional Development | K39: Professional Development
C40: 0.83333333 | D40: 0.85416667 | E40: OFFICE | F40: OFFICE | G40: OFFICE | H40: OFFICE | I40: OFFICE | J40: Professional Development | K40: Professional Development
C41: 0.85416667 | D41: 0.875 | E41: OFFICE | F41: OFFICE | G41: OFFICE | H41: OFFICE | I41: OFFICE
C42: 0.875 | D42: 0.89583333 | E42: OFFICE | F42: OFFICE | G42: OFFICE | H42: OFFICE | I42: OFFICE | J42: Book Publishing | K42: Book Publishing
C43: 0.89583333 | D43: 0.91666667 | E43: OFFICE | F43: OFFICE | G43: OFFICE | H43: OFFICE | I43: OFFICE | J43: Book Publishing | K43: Book Publishing
C44: 0.91666667 | D44: 0.9375 | E44: OFFICE | F44: OFFICE | G44: OFFICE | H44: OFFICE | I44: OFFICE | J44: Book Publishing | K44: Book Publishing
C45: 0.9375 | D45: 0.95833333 | E45: OFFICE | F45: OFFICE | G45: OFFICE | H45: OFFICE | I45: OFFICE | J45: Book Publishing | K45: Book Publishing
C46: 0.95833333 | D46: 0.97916667 | E46: OFFICE | F46: OFFICE | G46: OFFICE | H46: OFFICE | I46: OFFICE | J46: Book Publishing | K46: Book Publishing
...

Sheet Planned Expenses
A1: 44927 | F1: Balance | G1: Investment | H1: Investment | I1: Expense
D2: Pending | G2: Paid | H2: Paid | I2: Paid
A3: Fixed Factor | B3: 1000 | F3: Due Date | G3: 44580 | H3: 44583 | I3: 44928
A4: 17263.21 | D4: 0 | I4: Axis 2009
A5: Remaining | D5: Savings | E5: 45032 | F5: Balance | G5: Mutual Funds | H5: Mutual Funds | I5: CC Bill
A6: 3647.26 | D6: 0 | E6: ICICI 3945 | F6: 3647.26
A7: 10000.62 | D7: 0 | E7: Axis 0370 | F7: 10000.62 | G7: 500 | H7: 3000 | I7: 4526.4
A8: 500.98 | D8: 0 | E8: Axis 7503 | F8: 500.98
A9: 513.57 | D9: 0 | E9: HSBC 9006 | F9: 513.57
A10: 2100 | D10: 0 | E10: Paytm 4366 | F10: 2100
A11: 500.78 | D11: 0 | E11: SBI 5825 | F11: 500.78
A12: 0 | D12: 0 | E12: Paytm Wallet | F12: 0
A13: 0 | D13: 0 | E13: Phonepe Wallet | F13: 0
A15: 44958 | F15: Balance | G15: Investment | H15: Investment | I15: Expense
D16: Pending | G16: Paid | H16: Paid | I16: Paid
A17: Fixed Factor | B17: 1000 | F17: Due Date | G17: 44945 | H17: 44950 | I17: 44928
A18: 3552.81 | D18: 0 | I18: Axis 2009
A19: Remaining | D19: Savings | E19: 45032 | F19: Balance | G19: Mutual Funds | H19: Mutual Funds | I19: CC Bill
A20: 210.47 | D20: 0 | E20: ICICI 3945 | F20: 210.47
A21: 1018.5 | D21: 0 | E21: Axis 0370 | F21: 1018.5 | G21: 500 | H21: 3000 | I21: 1642.56
A22: 52.98 | D22: 0 | E22: Axis 7503 | F22: 52.98
A23: 1024.57 | D23: 0 | E23: HSBC 9006 | F23: 1024.57
A24: 83 | D24: 0 | E24: Paytm 4366 | F24: 83
A25: 9.28 | D25: 0 | E25: SBI 5825 | F25: 9.28
A26: 154.01 | D26: 0 | E26: Paytm Wallet | F26: 154.01
A27: 1000 | D27: 0 | E27: Phonepe Wallet | F27: 1000
A29: 44986 | F29: Balance | G29: Investment | H29: Investment | I29: Expense
D30: Pending | E30: 128596.81 | G30: Paid | H30: Paid | I30: Paid
A31: Fixed Factor | B31: 1000 | F31: Due Date | G31: 45004 | H31: 45007 | I31: 44928
A32: 4283.83 | B32: 18000 | D32: 0 | E32: 44986 | F32: 30734.83 | I32: Axis 2009
A33: Remaining | B33: Fixed Balance | D33: Savings | E33: 45032 | F33: Balance | G33: Mutual Funds | H33: Mutual Funds | I33: CC Bill
A34: 169.15 | B34: 3000 | D34: 0 | E34: ICICI 3945 | F34: 3213.15
A35: 561.48 | B35: 3000 | D35: 0 | E35: Axis 0370 | F35: 11968.48 | G35: 500 | H35: 3000 | I35: 0
A36: 72.91 | B36: 3000 | D36: 0 | E36: Axis 7503 | F36: 3072.91
A37: 1109.75 | B37: 3000 | D37: 0 | E37: HSBC 9006 | F37: 4109.75
A38: 100 | B38: 3000 | D38: 0 | E38: Paytm 4366 | F38: 3100
A39: 17.28 | B39: 3000 | D39: 0 | E39: SBI 5825 | F39: 3017.28
A40: 963.83 | B40: 0 | D40: 0 | E40: Paytm Wallet | F40: 963.83
A41: 1108.8 | B41: 0 | D41: 0 | E41: Phonepe Wallet | F41: 1108.8
A42: 180.63 | B42: 0 | D42: 0 | E42: Splitwise | F42: 180.63
...

Sheet Trading
K3: Partnership Start | M3: 45812
K4: Ratio | L4: =L$6/$G$6% -> 92 | M4: =M$6/$G$6% -> 8
L5: Aditya | M5: Laxmi Narayana
G6: =sum(L6:AH6) -> 250000 | K6: Investment | L6: 230000 | M6: 20000
K7: P&L Balance | L7: =round(L6+B9,0) -> 242012 | M7: =round(M6+C9,0) -> 20631
B9: =sum(B11:B1003) -> 12011.843 | C9: =sum(C11:C1003) -> 631.36728
A10: Commission | B10: =L10 -> Aditya | C10: =M10 -> Laxmi Narayana | D10: Date | E10: Trade | F10: Investment | G10: Traded | H10: P&L | I10: Charges | J10: Brokerage | K10: Net Realised Profit | L10: =L5 -> Aditya | M10: =M5 -> Laxmi Narayana
A11: =if(H11>0,M11*10%,0) -> 0 | B11: 3047.08 | C11: 0 | D11: 45811 | E11: Jindal Stainless Cochin Shipyard | H11: 3273.4 | I11: 146.32 | J11: 80 | K11: 3047.08 | L11: 3047.08 | M11: 0 | P11: 45811 | Q11: 4 | R11: 3273.4 | S11: 3047.08 | T11: 146.32
A12: 23.67312 | B12: 2746.0819 | C12: 213.05808 | D12: 45812 | E12: Inventurus Knowledge Solutions | F12: 238560 | G12: 47616.766 | H12: 3091.3 | I12: 92.16 | J12: 40 | K12: 2959.15 | L12: 2722.4088 | M12: 236.7312 | P12: 45812 | Q12: 2 | R12: 3091.3 | S12: 2959.15 | T12: 92.16
A13: 0 | B13: -584.9728 | C13: -50.8672 | D13: 45813 | E13: PB FinTech | F13: 187800 | G13: 37485.03 | H13: -521.6 | I13: 74.24 | J13: 40 | K13: -635.84 | L13: -584.9728 | M13: -50.8672 | P13: 45813 | Q13: 2 | R13: -521.6 | S13: -635.84 | T13: 74.24
A14: 63.46624 | B14: 7362.0838 | C14: 571.19616 | D14: 45814 | E14: Godrej Properties Macrotek Developers | H14: 8195 | I14: 181.72 | J14: 80 | K14: 7933.28 | L14: 7298.6176 | M14: 634.6624 | P14: 45814 | Q14: 4 | R14: 8195 | S14: 7933.28 | T14: 181.72
A15: 17.114 | B15: 1985.224 | C15: 154.026 | D15: 45817 | E15: Muthoot Finance | H15: 2276.4 | I15: 97.15 | J15: 40 | K15: 2139.25 | L15: 1968.11 | M15: 171.14 | P15: 45817 | Q15: 2 | R15: 2276.4 | S15: 2139.25 | T15: ₹ 97.15
A16: =if(H16>0,M16*10%,0) -> 6.7064 | B16: =L16+A16 -> 777.9424 | C16: =M16-A16 -> 60.3576 | D16: 45820 | H16: 1250.98 | K16: 838.3 | L16: =$K16*L$4/100 -> 771.236 | M16: =$K16*M$4/100 -> 67.064 | P16: 45820 | Q16: 6 | R16: 1250.98 | S16: 838.3 | T16: ₹ 292.68
A17: =if(H17>0,M17*10%,0) -> 25.36336 | B17: =L17+A17 -> 2942.1498 | C17: =M17-A17 -> 228.27024 | D17: 45832 | H17: 3691.37 | K17: 3170.42 | L17: =$K17*L$4/100 -> 2916.7864 | M17: =$K17*M$4/100 -> 253.6336 | P17: 45832 | Q17: 8 | R17: 3691.37 | S17: 3170.42 | T17: ₹ 360.95
A18: =if(H18>0,M18*10%,0) -> 0 | B18: =L18+A18 -> -6263.7464 | C18: =M18-A18 -> -544.6736 | D18: 45835 | H18: -6280.08 | K18: -6808.42 | L18: =$K18*L$4/100 -> -6263.7464 | M18: =$K18*M$4/100 -> -544.6736 | P18: 45835 | Q18: 8 | R18: -6280.08 | S18: -6808.42 | T18: ₹ 368.34
A19: =if(H19>0,M19*10%,0) -> 0 | B19: =L19+A19 -> 0 | C19: =M19-A19 -> 0 | K19: 0 | L19: =$K19*L$4/100 -> 0 | M19: =$K19*M$4/100 -> 0
A20: =if(H20>0,M20*10%,0) -> 0 | B20: =L20+A20 -> 0 | C20: =M20-A20 -> 0 | K20: 0 | L20: =$K20*L$4/100 -> 0 | M20: =$K20*M$4/100 -> 0
A21: =if(H21>0,M21*10%,0) -> 0 | B21: =L21+A21 -> 0 | C21: =M21-A21 -> 0 | K21: 0 | L21: =$K21*L$4/100 -> 0 | M21: =$K21*M$4/100 -> 0
A22: =if(H22>0,M22*10%,0) -> 0 | B22: =L22+A22 -> 0 | C22: =M22-A22 -> 0 | K22: 0 | L22: =$K22*L$4/100 -> 0 | M22: =$K22*M$4/100 -> 0
A23: =if(H23>0,M23*10%,0) -> 0 | B23: =L23+A23 -> 0 | C23: =M23-A23 -> 0 | K23: 0 | L23: =$K23*L$4/100 -> 0 | M23: =$K23*M$4/100 -> 0
A24: =if(H24>0,M24*10%,0) -> 0 | B24: =L24+A24 -> 0 | C24: =M24-A24 -> 0 | K24: 0 | L24: =$K24*L$4/100 -> 0 | M24: =$K24*M$4/100 -> 0
A25: =if(H25>0,M25*10%,0) -> 0 | B25: =L25+A25 -> 0 | C25: =M25-A25 -> 0 | K25: 0 | L25: =$K25*L$4/100 -> 0 | M25: =$K25*M$4/100 -> 0
A26: =if(H26>0,M26*10%,0) -> 0 | B26: =L26+A26 -> 0 | C26: =M26-A26 -> 0 | K26: 0 | L26: =$K26*L$4/100 -> 0 | M26: =$K26*M$4/100 -> 0
A27: =if(H27>0,M27*10%,0) -> 0 | B27: =L27+A27 -> 0 | C27: =M27-A27 -> 0 | K27: 0 | L27: =$K27*L$4/100 -> 0 | M27: =$K27*M$4/100 -> 0
A28: =if(H28>0,M28*10%,0) -> 0 | B28: =L28+A28 -> 0 | C28: =M28-A28 -> 0 | K28: 0 | L28: =$K28*L$4/100 -> 0 | M28: =$K28*M$4/100 -> 0
A29: =if(H29>0,M29*10%,0) -> 0 | B29: =L29+A29 -> 0 | C29: =M29-A29 -> 0 | K29: 0 | L29: =$K29*L$4/100 -> 0 | M29: =$K29*M$4/100 -> 0
A30: =if(H30>0,M30*10%,0) -> 0 | B30: =L30+A30 -> 0 | C30: =M30-A30 -> 0 | K30: 0 | L30: =$K30*L$4/100 -> 0 | M30: =$K30*M$4/100 -> 0
... A1003: =if(H1003>0,M1003*10%,0) -> 0 | B1003: =L1003+A1003 -> 0 | C1003: =M1003-A1003 -> 0 | K1003: 0 | L1003: =$K1003*L$4/100 -> 0 | M1003: =$K1003*M$4/100 -> 0

Sheet CC Outstanding
V3: Without Car | W3: =W6-W10 -> 67146 | Z3: =Z6-Z10 -> 1895446.1
B4: Credit Card Details | C4: 45809 | F4: =sum(F6:F9) -> 562037.76 | O4: =sum(O6:O1000) -> 16359
D5: Total Credit Limit | E5: Available Credit Limit | F5: Credit Card Outstanding | O5: MF | U5: =145649 -> 145649 | V5: Income
C6: ICICI 3002 | D6: 790000 | E6: 651214.46 | F6: =D6-E6 -> 138785.54 | O6: 6895 | U6: =sum(W6:AP6) -> 2912722 | V6: Loans | W6: =sum(W8:W1000) -> 79916 | X6: =sum(X8:X1000) -> 69000 | Z6: =sum(Z8:Z1000) -> 2763806
C7: ICICI 7018 ICICI 3003 ICICI 20010 | D7: 660000 | E7: 367662.93 | F7: =D7-E7 -> 292337.07 | O7: 6781 | AE7: 4003 | AF7: 3002 | AG7: 7018 | AH7: 7221
C8: ICICI 4003 | D8: 790000 | E8: 745719.62 | F8: =D8-E8 -> 44280.38 | O8: 33 | V8: Money View | W8: 9290 | Z8: =AA8*AD8 -> 399470 | AA8: 9290 | AB8: 48 | AC8: 5 | AD8: =AB8-AC8 -> 43
C9: AXIS 2009 AXIS 7221 | D9: 118000 | E9: 31365.23 | F9: =D9-E9 -> 86634.77 | O9: 1821 | V9: Bajaj | W9: 15577 | Z9: =AA9*AD9 -> 560772 | AA9: 15577 | AB9: 60 | AC9: 24 | AD9: =AB9-AC9 -> 36
O10: 829 | V10: Car | W10: 12770 | Z10: =AA10*AD10 -> 868360 | AA10: 12770 | AB10: =12*7 -> 84 | AC10: 16 | AD10: =AB10-AC10 -> 68
B11: Credit Card Details | C11: 45778 | F11: =sum(F13:F16) -> 606851.1 | L11: =sum(L13:L17) -> 842 | V11: ICICI CC | W11: 32319 | Z11: =sum(AE11:AH11) -> 659716.4 | AE11: =790000-714397.54 -> 75602.46 | AF11: =790000-668627.03 -> 121372.97 | AG11: =790660-327919.03 -> 462740.97
D12: Total Credit Limit | E12: Available Credit Limit | F12: Credit Card Outstanding | L12: Per Day | V12: Axis CC | W12: 6988 | Z12: =sum(AE12:AH12) -> 95487.65 | AH12: =118000-22512.35 -> 95487.65
C13: ICICI 3002 | D13: 790000 | E13: 636907.68 | F13: =D13-E13 -> 153092.32 | K13: Soujanya | L13: =floor(850*3/7,1) -> 364 | V13: Axis Personal Loan | W13: 2972 | Z13: =AA13*AD13 -> 180000 | AA13: 3000 | AB13: 60 | AC13: 0 | AD13: =AB13-AC13 -> 60
C14: ICICI 7018 ICICI 3003 ICICI 20010 | D14: 660000 | E14: 343967.47 | F14: =D14-E14 -> 316032.53 | K14: Hafiz | L14: =floor(670*5/7,1) -> 478
C15: ICICI 4003 | D15: 790000 | E15: 743257.35 | F15: =D15-E15 -> 46742.65 | V15: STR Residency | X15: 5000
C16: AXIS 2009 AXIS 7221 | D16: 118000 | E16: 27016.4 | F16: =D16-E16 -> 90983.6 | V16: Responsibilities | X16: 55000
V17: Utility | X17: 5000
V18: Savings | X18: 2000
V19: Investments | X19: 2000
V48: Add Income Transaction
V49: Add Expense Transaction
V50: Update Balance Transaction | W50: sometimes, expense transaction may be missed, so need update balance
V51: Set EMIs | W51: for credit card, loans etc.
V52: Update Credit Card Bills
V53: Reminder for interest payments

Sheet EMI Sheet
A1: Card | B1: Merchant Name | C1: Original Amount | D1: Tenure | E1: EMI Amt With Interest | F1: Pending EMI | G1: EMI Creation Date | H1: End Date | I1: Status Of EMI Transaction | J1: Balance | K1: Rank | L1: Total Loan | M1: EMI Interest | N1: Rank
A2: ICICI 7018 | B2: PLCC | C2: 260000 | D2: 24 | E2: 12605.29 | F2: 17 | G2: 45363 | H2: 46092 | I2: Active | J2: =F2*E2 -> 214289.93 | K2: =rank(J2,J$2:J$20) -> 1 | L2: =E2*D2 -> 302526.96 | M2: =(L2-J2)/D2 -> 3676.5429 | N2: =rank(M2,M$2:M$20) -> 1 | R2: 783 | S2: done
A3: ICICI 7018 | B3: Merchant EMI | C3: 118800 | D3: 24 | E3: 5477.63 | F3: 12 | G3: 13-06-2024 | H3: 13-05-2026 | I3: Active | J3: =F3*E3 -> 65731.56 | K3: =rank(J3,J$2:J$20) -> 2 | L3: =E3*D3 -> 131463.12 | M3: =(L3-J3)/D3 -> 2738.815 | N3: =rank(M3,M$2:M$20) -> 2 | R3: 792
A4: ICICI 3002 | B4: IND*AMAZON PGSI | C4: 86908 | D4: 24 | E4: 4254.87 | F4: 14 | G4: 45391 | H4: 46120 | I4: Active | J4: =F4*E4 -> 59568.18 | K4: =rank(J4,J$2:J$20) -> 3 | L4: =E4*D4 -> 102116.88 | M4: =(L4-J4)/D4 -> 1772.8625 | N4: =rank(M4,M$2:M$20) -> 3 | R4: 1547 | S4: done
A5: ICICI 4003 | B5: Merchant EMI | C5: 45499.42 | D5: 24 | E5: 2129.09 | F5: 21 | G5: 45780 | H5: 46509 | I5: Active | J5: =F5*E5 -> 44710.89 | K5: =rank(J5,J$2:J$20) -> 4 | L5: =E5*D5 -> 51098.16 | M5: =(L5-J5)/D5 -> 266.13625 | N5: =rank(M5,M$2:M$20) -> 7 | R5: 1682
A6: ICICI 3002 | B6: IND*AMAZON PGSI | C6: 40242.76 | D6: 9 | E6: 4774.58 | F6: 7 | G6: 30-04-2025 | H6: 30-12-2025 | I6: Active | J6: =F6*E6 -> 33422.06 | K6: =rank(J6,J$2:J$20) -> 5 | L6: =E6*D6 -> 42971.22 | M6: =(L6-J6)/D6 -> 1061.0178 | N6: =rank(M6,M$2:M$20) -> 4 | R6: 3474
A7: ICICI 7018 | B7: APPLE INDIA PRIVATE LI | C7: 22823 | D7: 6 | E7: 3983.19 | F7: 5 | G7: 45813 | H7: 45818 | I7: Active | J7: =F7*E7 -> 19915.95 | K7: =rank(J7,J$2:J$20) -> 6 | L7: =E7*D7 -> 23899.14 | M7: =(L7-J7)/D7 -> 663.865 | N7: =rank(M7,M$2:M$20) -> 5 | R7: 1742 | S7: done
A8: ICICI 3002 | B8: IND*AMAZON PGSI | C8: 20653.26 | D8: 24 | E8: 1011.15 | F8: 16 | G8: 29-10-2024 | H8: 29-09-2026 | I8: Active | J8: =F8*E8 -> 16178.4 | K8: =rank(J8,J$2:J$20) -> 7 | L8: =E8*D8 -> 24267.6 | M8: =(L8-J8)/D8 -> 337.05 | N8: =rank(M8,M$2:M$20) -> 6 | R8: 3221 | S8: done
A9: ICICI 3002 | B9: IND*AMAZON PGSI | C9: 13999 | D9: 24 | E9: 685.37 | F9: 15 | G9: 45574 | H9: 46303 | I9: Active | J9: =F9*E9 -> 10280.55 | K9: =rank(J9,J$2:J$20) -> 8 | L9: =E9*D9 -> 16448.88 | M9: =(L9-J9)/D9 -> 257.01375 | N9: =rank(M9,M$2:M$20) -> 8 | R9: 3179
A10: ICICI 3002 | B10: IND*AMAZON | C10: 9822 | D10: 24 | E10: 490.36 | F10: 18 | G10: 45455 | H10: 46184 | I10: Active | J10: =F10*E10 -> 8826.48 | K10: =rank(J10,J$2:J$20) -> 9 | L10: =E10*D10 -> 11768.64 | M10: =(L10-J10)/D10 -> 122.59 | N10: =rank(M10,M$2:M$20) -> 10
A11: ICICI 7018 | B11: BALAJI XTENSION | C11: 7880 | D11: 24 | E11: 393.4 | F11: 17 | G11: 45334 | H11: 46064 | I11: Active | J11: =F11*E11 -> 6687.8 | K11: =rank(J11,J$2:J$20) -> 11 | L11: =E11*D11 -> 9441.6 | M11: =(L11-J11)/D11 -> 114.74167 | N11: =rank(M11,M$2:M$20) -> 12
A12: ICICI 3002 | B12: IND*AMAZON PGSI | C12: 7299 | D12: 24 | E12: 357.35 | F12: 21 | G12: 18-03-2025 | H12: 18-02-2027 | I12: Active | J12: =F12*E12 -> 7504.35 | K12: =rank(J12,J$2:J$20) -> 10 | L12: =E12*D12 -> 8576.4 | M12: =(L12-J12)/D12 -> 44.66875 | N12: =rank(M12,M$2:M$20) -> 17
A13: ICICI 7018 | B13: CENTRO | C13: 6897.4 | D13: 24 | E13: 344.35 | F13: 7 | G13: 24-01-2024 | H13: 24-12-2025 | I13: Active | J13: =F13*E13 -> 2410.45 | K13: =rank(J13,J$2:J$20) -> 16 | L13: =E13*D13 -> 8264.4 | M13: =(L13-J13)/D13 -> 243.91458 | N13: =rank(M13,M$2:M$20) -> 9
A14: ICICI 3002 | B14: IBRAHIM BROS EXTENSION | C14: 5800 | D14: 24 | E14: 289.56 | F14: 18 | G14: 20-12-2024 | H14: 20-11-2026 | I14: Active | J14: =F14*E14 -> 5212.08 | K14: =rank(J14,J$2:J$20) -> 12 | L14: =E14*D14 -> 6949.44 | M14: =(L14-J14)/D14 -> 72.39 | N14: =rank(M14,M$2:M$20) -> 14
A15: ICICI 4003 | B15: UPI-776178736984-JS WINES | C15: 5010 | D15: 24 | E15: 250.12 | F15: 17 | G15: 45334 | H15: 46064 | I15: Active | J15: =F15*E15 -> 4252.04 | K15: =rank(J15,J$2:J$20) -> 13 | L15: =E15*D15 -> 6002.88 | M15: =(L15-J15)/D15 -> 72.951667 | N15: =rank(M15,M$2:M$20) -> 13
A16: ICICI 3002 | B16: IND*AMAZON PGSI | C16: 4008.96 | D16: 6 | E16: 699.67 | F16: 5 | G16: 45874 | H16: 45879 | I16: Active | J16: =F16*E16 -> 3498.35 | K16: =rank(J16,J$2:J$20) -> 14 | L16: =E16*D16 -> 4198.02 | M16: =(L16-J16)/D16 -> 116.61167 | N16: =rank(M16,M$2:M$20) -> 11
A17: ICICI 3002 | B17: MANISHA GULATI | C17: 3799 | D17: 24 | E17: 189.66 | F17: 18 | G17: 20-12-2024 | H17: 20-11-2026 | I17: Active | J17: =F17*E17 -> 3413.88 | K17: =rank(J17,J$2:J$20) -> 15 | L17: =E17*D17 -> 4551.84 | M17: =(L17-J17)/D17 -> 47.415 | N17: =rank(M17,M$2:M$20) -> 15
A18: ICICI 3002 | B18: IND*AMAZON PGSI | C18: 2877.75 | D18: 24 | E18: 140.89 | F18: 16 | G18: 15-10-2024 | H18: 15-09-2026 | I18: Active | J18: =F18*E18 -> 2254.24 | K18: =rank(J18,J$2:J$20) -> 18 | L18: =E18*D18 -> 3381.36 | M18: =(L18-J18)/D18 -> 46.963333 | N18: =rank(M18,M$2:M$20) -> 16
A19: ICICI 3002 | B19: VOYLLA 11 | C19: 2524 | D19: 24 | E19: 126.01 | F19: 18 | G19: 20-12-2024 | H19: 20-11-2026 | I19: Active | J19: =F19*E19 -> 2268.18 | K19: =rank(J19,J$2:J$20) -> 17 | L19: =E19*D19 -> 3024.24 | M19: =(L19-J19)/D19 -> 31.5025 | N19: =rank(M19,M$2:M$20) -> 19
A20: ICICI 3002 | B20: IND*AMAZON PGSI | C20: 1527 | D20: 6 | E20: 266.5 | F20: 5 | G20: 30-05-2025 | H20: 30-10-2025 | I20: Active | J20: =F20*E20 -> 1332.5 | K20: =rank(J20,J$2:J$20) -> 19 | L20: =E20*D20 -> 1599 | M20: =(L20-J20)/D20 -> 44.416667 | N20: =rank(M20,M$2:M$20) -> 18

Sheet Bills - CC EMIs
D1: =sum(J1:AH1) -> 0 | I1: Subject | J1: ICICI 7018 | K1: ICICI 7018 | L1: ICICI 7018 | M1: ICICI 3002 | N1: ICICI 4003 | O1: ICICI 3002 | P1: ICICI 7018 | Q1: ICICI 3002 | R1: ICICI 3002 | S1: ICICI 3002 | T1: ICICI 7018 | U1: ICICI 3002 | V1: ICICI 7018 | W1: ICICI 3002 | X1: ICICI 4003 | Y1: ICICI 3002 | Z1: ICICI 3002 | AA1: ICICI 3002 | AB1: ICICI 3002 | AC1: ICICI 3002
B2: 4173.59 | G2: SR 1015104860 | I2: Merchant Name | J2: PLCC | K2: Merchant EMI | L2: Personal loan | M2: IND*AMAZON PGSI | N2: Merchant EMI | O2: IND*AMAZON PGSI | P2: APPLE INDIA PRIVATE LI | Q2: IND*AMAZON PGSI | R2: IND*AMAZON PGSI | S2: IND*AMAZON | T2: BALAJI XTENSION | U2: IND*AMAZON PGSI | V2: CENTRO | W2: IBRAHIM BROS EXTENSION | X2: UPI-776178736984-JS WINES | Y2: IND*AMAZON PGSI | Z2: MANISHA GULATI | AA2: IND*AMAZON PGSI | AB2: VOYLLA 11 | AC2: IND*AMAZON PGSI
B3: 271.28 | I3: Original Amount | J3: 260000 | K3: 118800 | L3: 100000 | M3: 86908 | N3: 45499.42 | O3: 40242.76 | P3: 22823 | Q3: 20653.26 | R3: 13999 | S3: 9822 | T3: 7880 | U3: 7299 | V3: 6897.4 | W3: 5800 | X3: 5010 | Y3: 4008.96 | Z3: 3799 | AA3: 2877.75 | AB3: 2524 | AC3: 1527 | AD3: 2675.38 | AE3: 5280 | AF3: 2869.14 | AG3: 2825.61 | AH3: 2811.74 | AI3: 2719.11 | AJ3: 2681.27 | AK3: 2560.79 | AL3: 3093 | AM3: 3663.54 | AN3: 2991 | AO3: 2816.99 | AP3: 2323.72 | AQ3: 2470 | AR3: 2591.94 | AS3: 1505 | AT3: 12961 | AU3: 2274 | AV3: 4720 | AW3: 2710 | AX3: 2235.79 | AY3: 2300 | AZ3: 2508.5 | BA3: 2332 | BB3: 2804.57 | BC3: 2568.89 | BD3: 10496 | BE3: 7405 | BF3: 3815
B4: 145822.76 | I4: Tenure | J4: 24 | K4: 24 | L4: 24 | M4: 24 | N4: 24 | O4: 9 | P4: 6 | Q4: 24 | R4: 24 | S4: 24 | T4: 24 | U4: 24 | V4: 24 | W4: 24 | X4: 24 | Y4: 6 | Z4: 24 | AA4: 24 | AB4: 24 | AC4: 6 | AD4: 12 | AE4: 12 | AF4: 12 | AG4: 12 | AH4: 12 | AI4: 12 | AJ4: 12 | AK4: 12 | AL4: 12 | AM4: 12 | AN4: 12 | AO4: 12 | AP4: 12 | AQ4: 12 | AR4: 12 | AS4: 12 | AT4: 12 | AU4: 12 | AV4: 24 | AW4: 24 | AX4: 24 | AY4: 24 | AZ4: 24 | BA4: 24 | BB4: 24 | BC4: 24 | BD4: 24 | BE4: 24 | BF4: 24
I5: EMI Amt With Interest | J5: 12605.29 | K5: 5477.63 | L5: 5477.63 | M5: 4254.87 | N5: 2129.09 | O5: 4774.58 | P5: 3983.19 | Q5: 1011.15 | R5: 685.37 | S5: 490.36 | T5: 393.4 | U5: 357.35 | V5: 344.35 | W5: 289.56 | X5: 250.12 | Y5: 699.67 | Z5: 189.66 | AA5: 140.89 | AB5: 126.01 | AC5: 266.5 | AD5: 248.75 | AE5: 490.91 | AF5: 266.76 | AG5: 262.71 | AH5: 261.42 | AI5: 252.81 | AJ5: 249.29 | AK5: 238.09 | AL5: 287.57 | AM5: 340.62 | AN5: 278.09 | AO5: 261.91 | AP5: 216.37 | AQ5: 229.99 | AR5: 241.35 | AS5: 140.14 | AT5: 1206.85 | AU5: 211.74 | AV5: 235.64 | AW5: 135.29 | AX5: 111.62 | AY5: 114.83 | AZ5: 125.23 | BA5: 116.42 | BB5: 140.02 | BC5: 128.25 | BD5: 524 | BE5: 369.69 | BF5: 190.46
I6: Pending EMI | J6: 17 | K6: 12 | L6: 12 | M6: 14 | N6: 21 | O6: 7 | P6: 5 | Q6: 16 | R6: 15 | S6: 18 | T6: 17 | U6: 21 | V6: 7 | W6: 18 | X6: 17 | Y6: 5 | Z6: 18 | AA6: 16 | AB6: 18 | AC6: 5 | AD6: 4 | AE6: 4 | AF6: 4 | AG6: 4 | AH6: 4 | AI6: 4 | AJ6: 4 | AK6: 5 | AL6: 6 | AM6: 6 | AN6: 6 | AO6: 6 | AP6: 7 | AQ6: 7 | AR6: 7 | AS6: 7 | AT6: 7 | AU6: 7 | AV6: 20 | AW6: 20 | AX6: 20 | AY6: 21 | AZ6: 21 | BA6: 21 | BB6: 21 | BC6: 22 | BD6: 22 | BE6: 24 | BF6: 24
I7: 1st EMI | J7: 45363 | K7: 13-06-2024 | L7: 13-06-2024 | M7: 45391 | N7: 45780 | O7: 30-04-2025 | P7: 45813 | Q7: 29-10-2024 | R7: 45574 | S7: 45455 | T7: 45334 | U7: 18-03-2025 | V7: 24-01-2024 | W7: 20-12-2024 | X7: 45334 | Y7: 45874 | Z7: 20-12-2024 | AA7: 15-10-2024 | AB7: 20-12-2024 | AC7: 30-05-2025 | AD7: 45565 | AE7: 45565 | AF7: 45565 | AG7: 45565 | AH7: 45565 | AI7: 45565 | AJ7: 45565 | AK7: 45593 | AL7: 45629 | AM7: 45632 | AN7: 45632 | AO7: 45632 | AP7: 45647 | AQ7: 45647 | AR7: 45658 | AS7: 45670 | AT7: 45670 | AU7: 45677 | AV7: 45701 | AW7: 45708 | AX7: 45708 | AY7: 45718 | AZ7: 45718 | BA7: 45732 | BB7: 45732 | BC7: 45754 | BD7: 45754 | BE7: 45802 | BF7: 45802
B8: 45383 | I8: Last EMI | J8: 46092 | K8: 13-05-2026 | L8: 13-05-2026 | M8: 46120 | N8: 46509 | O8: 30-12-2025 | P8: 45818 | Q8: 29-09-2026 | R8: 46303 | S8: 46184 | T8: 46064 | U8: 18-02-2027 | V8: 24-12-2025 | W8: 20-11-2026 | X8: 46064 | Y8: 45879 | Z8: 20-11-2026 | AA8: 15-09-2026 | AB8: 20-11-2026 | AC8: 30-10-2025 | AD8: =edate(AD7,AD4) -> 45930 | AE8: =edate(AE7,AE4) -> 45930 | AF8: =edate(AF7,AF4) -> 45930 | AG8: =edate(AG7,AG4) -> 45930 | AH8: =edate(AH7,AH4) -> 45930 | AI8: =edate(AI7,AI4) -> 45930 | AJ8: =edate(AJ7,AJ4) -> 45930 | AK8: =edate(AK7,AK4) -> 45958 | ... BF8: =edate(BF7,BF4) -> 46532
I9: Status Of EMI Transaction | J9: Active | K9: Active | L9: Active | M9: Active | N9: Active | O9: Active | P9: Active | Q9: Active | R9: Active | S9: Active | T9: Active | U9: Active | V9: Active | W9: Active | X9: Active | Y9: Active | Z9: Active | AA9: Active | AB9: Active | AC9: Active
I10: Status Of EMI Transaction
I11: Monthly Interest
B12: 224954 | G12: Start of Today | H12: =DATE(YEAR(today()),MONTH(TODAY()),1) -> 45962 | I12: Remaining Amount
I13: Remaining EMIs
I14: Today
I15: Principal
I16: Interest
I17: GST 18%
E18: =sum(E20:E117) -> 60187.91 | F18: =sum(F20:F117) -> 372547.12 | G18: =sum(G20:G117) -> 96524.51 | H18: =sum(H20:H117) -> 1783.9 | I18: Total EMI
A19: Remaining Loan Amount | B19: Total EMIs | C19: CC EMIs | D19: =sumif(I20:I117,"Future",B20:B117) -> 498306 | E19: ICICI CC 4003 | F19: ICICI CC 7018 | G19: ICICI CC 3002 | H19: AXIS 7221 | I19: Card | J19: ICICI CC 7018 | K19: ICICI CC 7018 | L19: ICICI CC 7018 | M19: ICICI CC 3002 | N19: ICICI CC 4003 | O19: ICICI CC 3002 | P19: ICICI CC 7018 | Q19: ICICI CC 3002 | R19: ICICI CC 3002 | S19: ICICI CC 3002 | T19: ICICI CC 7018 | U19: ICICI CC 3002 | V19: ICICI CC 7018 | W19: ICICI CC 3002 | X19: ICICI CC 4003 | Y19: ICICI CC 3002 | Z19: ICICI CC 3002 | AA19: ICICI CC 3002 | AB19: ICICI CC 3002 | AC19: ICICI CC 3002 | AD19: AXIS 7221 | AE19: AXIS 7221 | AF19: AXIS 7221 | AG19: AXIS 7221 | AH19: AXIS 7221 | AI19: AXIS 7221 | AJ19: AXIS 7221 | AK19: AXIS 7221 | AL19: AXIS 7221 | AM19: AXIS 7221 | AN19: AXIS 7221 | AO19: AXIS 7221 | AP19: AXIS 7221 | AQ19: AXIS 7221 | AR19: AXIS 7221 | AS19: AXIS 7221 | AT19: AXIS 7221 | AU19: AXIS 7221 | AV19: AXIS 7221 | AW19: AXIS 7221 | AX19: AXIS 7221 | AY19: AXIS 7221 | AZ19: AXIS 7221 | BA19: AXIS 7221 | BB19: AXIS 7221 | BC19: AXIS 7221 | BD19: AXIS 7221 | BE19: AXIS 7221 | BF19: AXIS 7221
A20: =ceiling(sum(J20:BF117)-sum(J20:BF20),1) -> 989504 | B20: =ceiling(sum(J20:BF20),1) -> 0 | C20: =sum(E20:H20) -> 0 | D20: 44805 | E20: =sumif($J$19:BF19,E$19,$J20:BF20) -> 0 | F20: =sumif($J$19:BG19,F$19,$J20:BG20) -> 0 | G20: =sumif($J$19:BH19,G$19,$J20:BH20) -> 0 | H20: =sumif($J$19:BI19,H$19,$J20:BI20) -> 0 | I20: =if(D20=DATE(year(today()),month(today()),1),"Current",if(D20>DATE(year(today()),month(today()),1), "Future","Past")) -> Past | AE20: =if(and($D20>AE$7,$D20<AE$8),AE$5,0) -> 0 | AF20: =if(and($D20>AF$7,$D20<AF$8),AF$5,0) -> 0 | AG20: =if(and($D20>AG$7,$D20<AG$8),AG$5,0) -> 0 | AH20: =if(and($D20>AH$7,$D20<AH$8),AH$5,0) -> 0 | AI20: =if(and($D20>AI$7,$D20<AI$8),AI$5,0) -> 0 | AJ20: =if(and($D20>AJ$7,$D20<AJ$8),AJ$5,0) -> 0 | AK20: =if(and($D20>AK$7,$D20<AK$8),AK$5,0) -> 0 | AL20: =if(and($D20>AL$7,$D20<AL$8),AL$5,0) -> 0 | ... BF20: =if(and($D20>BF$7,$D20<BF$8),BF$5,0) -> 0
A21: =ceiling(sum(J21:BF118)-sum(J21:BF21),1) -> 989504 | B21: =ceiling(sum(J21:BF21),1) -> 0 | C21: =sum(E21:H21) -> 0 | D21: 44835 | E21: =sumif($J$19:BF20,E$19,$J21:BF21) -> 0 | F21: =sumif($J$19:BG20,F$19,$J21:BG21) -> 0 | G21: =sumif($J$19:BH20,G$19,$J21:BH21) -> 0 | H21: =sumif($J$19:BI20,H$19,$J21:BI21) -> 0 | I21: =if(D21=DATE(year(today()),month(today()),1),"Current",if(D21>DATE(year(today()),month(today()),1), "Future","Past")) -> Past | AE21: =if(and($D21>AE$7,$D21<AE$8),AE$5,0) -> 0 | AF21: =if(and($D21>AF$7,$D21<AF$8),AF$5,0) -> 0 | AG21: =if(and($D21>AG$7,$D21<AG$8),AG$5,0) -> 0 | AH21: =if(and($D21>AH$7,$D21<AH$8),AH$5,0) -> 0 | AI21: =if(and($D21>AI$7,$D21<AI$8),AI$5,0) -> 0 | AJ21: =if(and($D21>AJ$7,$D21<AJ$8),AJ$5,0) -> 0 | AK21: =if(and($D21>AK$7,$D21<AK$8),AK$5,0) -> 0 | AL21: =if(and($D21>AL$7,$D21<AL$8),AL$5,0) -> 0 | ... BF21: =if(and($D21>BF$7,$D21<BF$8),BF$5,0) -> 0
A22: =ceiling(sum(J22:BF119)-sum(J22:BF22),1) -> 989504 | B22: =ceiling(sum(J22:BF22),1) -> 0 | C22: =sum(E22:H22) -> 0 | D22: 44866 | E22: =sumif($J$19:BF21,E$19,$J22:BF22) -> 0 | F22: =sumif($J$19:BG21,F$19,$J22:BG22) -> 0 | G22: =sumif($J$19:BH21,G$19,$J22:BH22) -> 0 | H22: =sumif($J$19:BI21,H$19,$J22:BI22) -> 0 | I22: =if(D22=DATE(year(today()),month(today()),1),"Current",if(D22>DATE(year(today()),month(today()),1), "Future","Past")) -> Past | AE22: =if(and($D22>AE$7,$D22<AE$8),AE$5,0) -> 0 | AF22: =if(and($D22>AF$7,$D22<AF$8),AF$5,0) -> 0 | AG22: =if(and($D22>AG$7,$D22<AG$8),AG$5,0) -> 0 | AH22: =if(and($D22>AH$7,$D22<AH$8),AH$5,0) -> 0 | AI22: =if(and($D22>AI$7,$D22<AI$8),AI$5,0) -> 0 | AJ22: =if(and($D22>AJ$7,$D22<AJ$8),AJ$5,0) -> 0 | AK22: =if(and($D22>AK$7,$D22<AK$8),AK$5,0) -> 0 | AL22: =if(and($D22>AL$7,$D22<AL$8),AL$5,0) -> 0 | ... BF22: =if(and($D22>BF$7,$D22<BF$8),BF$5,0) -> 0
A23: =ceiling(sum(J23:BF120)-sum(J23:BF23),1) -> 989504 | B23: =ceiling(sum(J23:BF23),1) -> 0 | C23: =sum(E23:H23) -> 0 | D23: 44896 | E23: =sumif($J$19:BF22,E$19,$J23:BF23) -> 0 | F23: =sumif($J$19:BG22,F$19,$J23:BG23) -> 0 | G23: =sumif($J$19:BH22,G$19,$J23:BH23) -> 0 | H23: =sumif($J$19:BI22,H$19,$J23:BI23) -> 0 | I23: =if(D23=DATE(year(today()),month(today()),1),"Current",if(D23>DATE(year(today()),month(today()),1), "Future","Past")) -> Past | AE23: =if(and($D23>AE$7,$D23<AE$8),AE$5,0) -> 0 | AF23: =if(and($D23>AF$7,$D23<AF$8),AF$5,0) -> 0 | AG23: =if(and($D23>AG$7,$D23<AG$8),AG$5,0) -> 0 | AH23: =if(and($D23>AH$7,$D23<AH$8),AH$5,0) -> 0 | AI23: =if(and($D23>AI$7,$D23<AI$8),AI$5,0) -> 0 | AJ23: =if(and($D23>AJ$7,$D23<AJ$8),AJ$5,0) -> 0 | AK23: =if(and($D23>AK$7,$D23<AK$8),AK$5,0) -> 0 | AL23: =if(and($D23>AL$7,$D23<AL$8),AL$5,0) -> 0 | ... BF23: =if(and($D23>BF$7,$D23<BF$8),BF$5,0) -> 0
A24: =ceiling(sum(J24:BF121)-sum(J24:BF24),1) -> 989504 | B24: =ceiling(sum(J24:BF24),1) -> 0 | C24: =sum(E24:H24) -> 0 | D24: 44927 | E24: =sumif($J$19:BF23,E$19,$J24:BF24) -> 0 | F24: =sumif($J$19:BG23,F$19,$J24:BG24) -> 0 | G24: =sumif($J$19:BH23,G$19,$J24:BH24) -> 0 | H24: =sumif($J$19:BI23,H$19,$J24:BI24) -> 0 | I24: =if(D24=DATE(year(today()),month(today()),1),"Current",if(D24>DATE(year(today()),month(today()),1), "Future","Past")) -> Past | AE24: =if(and($D24>AE$7,$D24<AE$8),AE$5,0) -> 0 | AF24: =if(and($D24>AF$7,$D24<AF$8),AF$5,0) -> 0 | AG24: =if(and($D24>AG$7,$D24<AG$8),AG$5,0) -> 0 | AH24: =if(and($D24>AH$7,$D24<AH$8),AH$5,0) -> 0 | AI24: =if(and($D24>AI$7,$D24<AI$8),AI$5,0) -> 0 | AJ24: =if(and($D24>AJ$7,$D24<AJ$8),AJ$5,0) -> 0 | AK24: =if(and($D24>AK$7,$D24<AK$8),AK$5,0) -> 0 | AL24: =if(and($D24>AL$7,$D24<AL$8),AL$5,0) -> 0 | ... BF24: =if(and($D24>BF$7,$D24<BF$8),BF$5,0) -> 0
A25: =ceiling(sum(J25:BF122)-sum(J25:BF25),1) -> 989504 | B25: =ceiling(sum(J25:BF25),1) -> 0 | C25: =sum(E25:H25) -> 0 | D25: 44958 | E25: =sumif($J$19:BF24,E$19,$J25:BF25) -> 0 | F25: =sumif($J$19:BG24,F$19,$J25:BG25) -> 0 | G25: =sumif($J$19:BH24,G$19,$J25:BH25) -> 0 | H25: =sumif($J$19:BI24,H$19,$J25:BI25) -> 0 | I25: =if(D25=DATE(year(today()),month(today()),1),"Current",if(D25>DATE(year(today()),month(today()),1), "Future","Past")) -> Past | AE25: =if(and($D25>AE$7,$D25<AE$8),AE$5,0) -> 0 | AF25: =if(and($D25>AF$7,$D25<AF$8),AF$5,0) -> 0 | AG25: =if(and($D25>AG$7,$D25<AG$8),AG$5,0) -> 0 | AH25: =if(and($D25>AH$7,$D25<AH$8),AH$5,0) -> 0 | AI25: =if(and($D25>AI$7,$D25<AI$8),AI$5,0) -> 0 | AJ25: =if(and($D25>AJ$7,$D25<AJ$8),AJ$5,0) -> 0 | AK25: =if(and($D25>AK$7,$D25<AK$8),AK$5,0) -> 0 | AL25: =if(and($D25>AL$7,$D25<AL$8),AL$5,0) -> 0 | ... BF25: =if(and($D25>BF$7,$D25<BF$8),BF$5,0) -> 0
A26: =ceiling(sum(J26:BF123)-sum(J26:BF26),1) -> 989504 | B26: =ceiling(sum(J26:BF26),1) -> 0 | C26: =sum(E26:H26) -> 0 | D26: 44986 | E26: =sumif($J$19:BF25,E$19,$J26:BF26) -> 0 | F26: =sumif($J$19:BG25,F$19,$J26:BG26) -> 0 | G26: =sumif($J$19:BH25,G$19,$J26:BH26) -> 0 | H26: =sumif($J$19:BI25,H$19,$J26:BI26) -> 0 | I26: =if(D26=DATE(year(today()),month(today()),1),"Current",if(D26>DATE(year(today()),month(today()),1), "Future","Past")) -> Past | AE26: =if(and($D26>AE$7,$D26<AE$8),AE$5,0) -> 0 | AF26: =if(and($D26>AF$7,$D26<AF$8),AF$5,0) -> 0 | AG26: =if(and($D26>AG$7,$D26<AG$8),AG$5,0) -> 0 | AH26: =if(and($D26>AH$7,$D26<AH$8),AH$5,0) -> 0 | AI26: =if(and($D26>AI$7,$D26<AI$8),AI$5,0) -> 0 | AJ26: =if(and($D26>AJ$7,$D26<AJ$8),AJ$5,0) -> 0 | AK26: =if(and($D26>AK$7,$D26<AK$8),AK$5,0) -> 0 | AL26: =if(and($D26>AL$7,$D26<AL$8),AL$5,0) -> 0 | ... BF26: =if(and($D26>BF$7,$D26<BF$8),BF$5,0) -> 0
A27: =ceiling(sum(J27:BF124)-sum(J27:BF27),1) -> 989504 | B27: =ceiling(sum(J27:BF27),1) -> 0 | C27: =sum(E27:H27) -> 0 | D27: 45017 | E27: =sumif($J$19:BF26,E$19,$J27:BF27) -> 0 | F27: =sumif($J$19:BG26,F$19,$J27:BG27) -> 0 | G27: =sumif($J$19:BH26,G$19,$J27:BH27) -> 0 | H27: =sumif($J$19:BI26,H$19,$J27:BI27) -> 0 | I27: =if(D27=DATE(year(today()),month(today()),1),"Current",if(D27>DATE(year(today()),month(today()),1), "Future","Past")) -> Past | AE27: =if(and($D27>AE$7,$D27<AE$8),AE$5,0) -> 0 | AF27: =if(and($D27>AF$7,$D27<AF$8),AF$5,0) -> 0 | AG27: =if(and($D27>AG$7,$D27<AG$8),AG$5,0) -> 0 | AH27: =if(and($D27>AH$7,$D27<AH$8),AH$5,0) -> 0 | AI27: =if(and($D27>AI$7,$D27<AI$8),AI$5,0) -> 0 | AJ27: =if(and($D27>AJ$7,$D27<AJ$8),AJ$5,0) -> 0 | AK27: =if(and($D27>AK$7,$D27<AK$8),AK$5,0) -> 0 | AL27: =if(and($D27>AL$7,$D27<AL$8),AL$5,0) -> 0 | ... BF27: =if(and($D27>BF$7,$D27<BF$8),BF$5,0) -> 0
A28: =ceiling(sum(J28:BF125)-sum(J28:BF28),1) -> 989504 | B28: =ceiling(sum(J28:BF28),1) -> 0 | C28: =sum(E28:H28) -> 0 | D28: 45047 | E28: =sumif($J$19:BF27,E$19,$J28:BF28) -> 0 | F28: =sumif($J$19:BG27,F$19,$J28:BG28) -> 0 | G28: =sumif($J$19:BH27,G$19,$J28:BH28) -> 0 | H28: =sumif($J$19:BI27,H$19,$J28:BI28) -> 0 | I28: =if(D28=DATE(year(today()),month(today()),1),"Current",if(D28>DATE(year(today()),month(today()),1), "Future","Past")) -> Past | AE28: =if(and($D28>AE$7,$D28<AE$8),AE$5,0) -> 0 | AF28: =if(and($D28>AF$7,$D28<AF$8),AF$5,0) -> 0 | AG28: =if(and($D28>AG$7,$D28<AG$8),AG$5,0) -> 0 | AH28: =if(and($D28>AH$7,$D28<AH$8),AH$5,0) -> 0 | AI28: =if(and($D28>AI$7,$D28<AI$8),AI$5,0) -> 0 | AJ28: =if(and($D28>AJ$7,$D28<AJ$8),AJ$5,0) -> 0 | AK28: =if(and($D28>AK$7,$D28<AK$8),AK$5,0) -> 0 | AL28: =if(and($D28>AL$7,$D28<AL$8),AL$5,0) -> 0 | ... BF28: =if(and($D28>BF$7,$D28<BF$8),BF$5,0) -> 0
A29: =ceiling(sum(J29:BF126)-sum(J29:BF29),1) -> 989504 | B29: =ceiling(sum(J29:BF29),1) -> 0 | C29: =sum(E29:H29) -> 0 | D29: 45078 | E29: =sumif($J$19:BF28,E$19,$J29:BF29) -> 0 | F29: =sumif($J$19:BG28,F$19,$J29:BG29) -> 0 | G29: =sumif($J$19:BH28,G$19,$J29:BH29) -> 0 | H29: =sumif($J$19:BI28,H$19,$J29:BI29) -> 0 | I29: =if(D29=DATE(year(today()),month(today()),1),"Current",if(D29>DATE(year(today()),month(today()),1), "Future","Past")) -> Past | AE29: =if(and($D29>AE$7,$D29<AE$8),AE$5,0) -> 0 | AF29: =if(and($D29>AF$7,$D29<AF$8),AF$5,0) -> 0 | AG29: =if(and($D29>AG$7,$D29<AG$8),AG$5,0) -> 0 | AH29: =if(and($D29>AH$7,$D29<AH$8),AH$5,0) -> 0 | AI29: =if(and($D29>AI$7,$D29<AI$8),AI$5,0) -> 0 | AJ29: =if(and($D29>AJ$7,$D29<AJ$8),AJ$5,0) -> 0 | AK29: =if(and($D29>AK$7,$D29<AK$8),AK$5,0) -> 0 | AL29: =if(and($D29>AL$7,$D29<AL$8),AL$5,0) -> 0 | ... BF29: =if(and($D29>BF$7,$D29<BF$8),BF$5,0) -> 0
A30: =ceiling(sum(J30:BF127)-sum(J30:BF30),1) -> 989504 | B30: =ceiling(sum(J30:BF30),1) -> 0 | C30: =sum(E30:H30) -> 0 | D30: 45108 | E30: =sumif($J$19:BF29,E$19,$J30:BF30) -> 0 | F30: =sumif($J$19:BG29,F$19,$J30:BG30) -> 0 | G30: =sumif($J$19:BH29,G$19,$J30:BH30) -> 0 | H30: =sumif($J$19:BI29,H$19,$J30:BI30) -> 0 | I30: =if(D30=DATE(year(today()),month(today()),1),"Current",if(D30>DATE(year(today()),month(today()),1), "Future","Past")) -> Past | AE30: =if(and($D30>AE$7,$D30<AE$8),AE$5,0) -> 0 | AF30: =if(and($D30>AF$7,$D30<AF$8),AF$5,0) -> 0 | AG30: =if(and($D30>AG$7,$D30<AG$8),AG$5,0) -> 0 | AH30: =if(and($D30>AH$7,$D30<AH$8),AH$5,0) -> 0 | AI30: =if(and($D30>AI$7,$D30<AI$8),AI$5,0) -> 0 | AJ30: =if(and($D30>AJ$7,$D30<AJ$8),AJ$5,0) -> 0 | AK30: =if(and($D30>AK$7,$D30<AK$8),AK$5,0) -> 0 | AL30: =if(and($D30>AL$7,$D30<AL$8),AL$5,0) -> 0 | ... BF30: =if(and($D30>BF$7,$D30<BF$8),BF$5,0) -> 0
A31: =ceiling(sum(J31:BF128)-sum(J31:BF31),1) -> 989504 | B31: =ceiling(sum(J31:BF31),1) -> 0 | C31: =sum(E31:H31) -> 0 | D31: 45139 | E31: =sumif($J$19:BF30,E$19,$J31:BF31) -> 0 | F31: =sumif($J$19:BG30,F$19,$J31:BG31) -> 0 | G31: =sumif($J$19:BH30,G$19,$J31:BH31) -> 0 | H31: =sumif($J$19:BI30,H$19,$J31:BI31) -> 0 | I31: =if(D31=DATE(year(today()),month(today()),1),"Current",if(D31>DATE(year(today()),month(today()),1), "Future","Past")) -> Past | AE31: =if(and($D31>AE$7,$D31<AE$8),AE$5,0) -> 0 | AF31: =if(and($D31>AF$7,$D31<AF$8),AF$5,0) -> 0 | AG31: =if(and($D31>AG$7,$D31<AG$8),AG$5,0) -> 0 | AH31: =if(and($D31>AH$7,$D31<AH$8),AH$5,0) -> 0 | AI31: =if(and($D31>AI$7,$D31<AI$8),AI$5,0) -> 0 | AJ31: =if(and($D31>AJ$7,$D31<AJ$8),AJ$5,0) -> 0 | AK31: =if(and($D31>AK$7,$D31<AK$8),AK$5,0) -> 0 | AL31: =if(and($D31>AL$7,$D31<AL$8),AL$5,0) -> 0 | ... BF31: =if(and($D31>BF$7,$D31<BF$8),BF$5,0) -> 0
... A36: =ceiling(sum(J36:BF133)-sum(J36:BF36),1) -> 989504 | B36: =ceiling(sum(J36:BF36),1) -> 0 | C36: =sum(E36:H36) -> 0 | D36: 45292 | E36: =sumif($J$19:BF35,E$19,$J36:BF36) -> 0 | F36: =sumif($J$19:BG35,F$19,$J36:BG36) -> 0 | G36: =sumif($J$19:BH35,G$19,$J36:BH36) -> 0 | H36: =sumif($J$19:BI35,H$19,$J36:BI36) -> 0 | I36: =if(D36=DATE(year(today()),month(today()),1),"Current",if(D36>DATE(year(today()),month(today()),1), "Future","Past")) -> Past | AE36: =if(and($D36>AE$7,$D36<AE$8),AE$5,0) -> 0 | AF36: =if(and($D36>AF$7,$D36<AF$8),AF$5,0) -> 0 | AG36: =if(and($D36>AG$7,$D36<AG$8),AG$5,0) -> 0 | AH36: =if(and($D36>AH$7,$D36<AH$8),AH$5,0) -> 0 | AI36: =if(and($D36>AI$7,$D36<AI$8),AI$5,0) -> 0 | AJ36: =if(and($D36>AJ$7,$D36<AJ$8),AJ$5,0) -> 0 | AK36: =if(and($D36>AK$7,$D36<AK$8),AK$5,0) -> 0 | AL36: =if(and($D36>AL$7,$D36<AL$8),AL$5,0) -> 0 | ... BF36: =if(and($D36>BF$7,$D36<BF$8),BF$5,0) -> 0
A37: =ceiling(sum(J37:BF134)-sum(J37:BF37),1) -> 989159 | B37: =ceiling(sum(J37:BF37),1) -> 345 | C37: =sum(E37:H37) -> 344.35 | D37: 45323 | E37: =sumif($J$19:BF36,E$19,$J37:BF37) -> 0 | F37: =sumif($J$19:BG36,F$19,$J37:BG37) -> 344.35 | G37: =sumif($J$19:BH36,G$19,$J37:BH37) -> 0 | H37: =sumif($J$19:BI36,H$19,$J37:BI37) -> 0 | I37: =if(D37=DATE(year(today()),month(today()),1),"Current",if(D37>DATE(year(today()),month(today()),1), "Future","Past")) -> Past | V37: =V$5 -> 344.35 | AE37: =if(and($D37>AE$7,$D37<AE$8),AE$5,0) -> 0 | AF37: =if(and($D37>AF$7,$D37<AF$8),AF$5,0) -> 0 | AG37: =if(and($D37>AG$7,$D37<AG$8),AG$5,0) -> 0 | AH37: =if(and($D37>AH$7,$D37<AH$8),AH$5,0) -> 0 | AI37: =if(and($D37>AI$7,$D37<AI$8),AI$5,0) -> 0 | AJ37: =if(and($D37>AJ$7,$D37<AJ$8),AJ$5,0) -> 0 | AK37: =if(and($D37>AK$7,$D37<AK$8),AK$5,0) -> 0 | AL37: =if(and($D37>AL$7,$D37<AL$8),AL$5,0) -> 0 | ... BF37: =if(and($D37>BF$7,$D37<BF$8),BF$5,0) -> 0
A38: =ceiling(sum(J38:BF135)-sum(J38:BF38),1) -> 988815 | B38: =ceiling(sum(J38:BF38),1) -> 345 | C38: =sum(E38:H38) -> 344.35 | D38: 45352 | E38: =sumif($J$19:BF37,E$19,$J38:BF38) -> 0 | F38: =sumif($J$19:BG37,F$19,$J38:BG38) -> 344.35 | G38: =sumif($J$19:BH37,G$19,$J38:BH38) -> 0 | H38: =sumif($J$19:BI37,H$19,$J38:BI38) -> 0 | I38: =if(D38=DATE(year(today()),month(today()),1),"Current",if(D38>DATE(year(today()),month(today()),1), "Future","Past")) -> Past | V38: =V$5 -> 344.35 | AE38: =if(and($D38>AE$7,$D38<AE$8),AE$5,0) -> 0 | AF38: =if(and($D38>AF$7,$D38<AF$8),AF$5,0) -> 0 | AG38: =if(and($D38>AG$7,$D38<AG$8),AG$5,0) -> 0 | AH38: =if(and($D38>AH$7,$D38<AH$8),AH$5,0) -> 0 | AI38: =if(and($D38>AI$7,$D38<AI$8),AI$5,0) -> 0 | AJ38: =if(and($D38>AJ$7,$D38<AJ$8),AJ$5,0) -> 0 | AK38: =if(and($D38>AK$7,$D38<AK$8),AK$5,0) -> 0 | AL38: =if(and($D38>AL$7,$D38<AL$8),AL$5,0) -> 0 | ... BF38: =if(and($D38>BF$7,$D38<BF$8),BF$5,0) -> 0
A39: =ceiling(sum(J39:BF136)-sum(J39:BF39),1) -> 988470 | B39: =ceiling(sum(J39:BF39),1) -> 345 | C39: =sum(E39:H39) -> 344.35 | D39: 45383 | E39: =sumif($J$19:BF38,E$19,$J39:BF39) -> 0 | F39: =sumif($J$19:BG38,F$19,$J39:BG39) -> 344.35 | G39: =sumif($J$19:BH38,G$19,$J39:BH39) -> 0 | H39: =sumif($J$19:BI38,H$19,$J39:BI39) -> 0 | I39: =if(D39=DATE(year(today()),month(today()),1),"Current",if(D39>DATE(year(today()),month(today()),1), "Future","Past")) -> Past | V39: =V$5 -> 344.35 | AE39: =if(and($D39>AE$7,$D39<AE$8),AE$5,0) -> 0 | AF39: =if(and($D39>AF$7,$D39<AF$8),AF$5,0) -> 0 | AG39: =if(and($D39>AG$7,$D39<AG$8),AG$5,0) -> 0 | AH39: =if(and($D39>AH$7,$D39<AH$8),AH$5,0) -> 0 | AI39: =if(and($D39>AI$7,$D39<AI$8),AI$5,0) -> 0 | AJ39: =if(and($D39>AJ$7,$D39<AJ$8),AJ$5,0) -> 0 | AK39: =if(and($D39>AK$7,$D39<AK$8),AK$5,0) -> 0 | AL39: =if(and($D39>AL$7,$D39<AL$8),AL$5,0) -> 0 | ... BF39: =if(and($D39>BF$7,$D39<BF$8),BF$5,0) -> 0
A40: =ceiling(sum(J40:BF137)-sum(J40:BF40),1) -> 988126 | B40: =ceiling(sum(J40:BF40),1) -> 345 | C40: =sum(E40:H40) -> 344.35 | D40: 45413 | E40: =sumif($J$19:BF39,E$19,$J40:BF40) -> 0 | F40: =sumif($J$19:BG39,F$19,$J40:BG40) -> 344.35 | G40: =sumif($J$19:BH39,G$19,$J40:BH40) -> 0 | H40: =sumif($J$19:BI39,H$19,$J40:BI40) -> 0 | I40: =if(D40=DATE(year(today()),month(today()),1),"Current",if(D40>DATE(year(today()),month(today()),1), "Future","Past")) -> Past | V40: =V$5 -> 344.35 | AE40: =if(and($D40>AE$7,$D40<AE$8),AE$5,0) -> 0 | AF40: =if(and($D40>AF$7,$D40<AF$8),AF$5,0) -> 0 | AG40: =if(and($D40>AG$7,$D40<AG$8),AG$5,0) -> 0 | AH40: =if(and($D40>AH$7,$D40<AH$8),AH$5,0) -> 0 | AI40: =if(and($D40>AI$7,$D40<AI$8),AI$5,0) -> 0 | AJ40: =if(and($D40>AJ$7,$D40<AJ$8),AJ$5,0) -> 0 | AK40: =if(and($D40>AK$7,$D40<AK$8),AK$5,0) -> 0 | AL40: =if(and($D40>AL$7,$D40<AL$8),AL$5,0) -> 0 | ... BF40: =if(and($D40>BF$7,$D40<BF$8),BF$5,0) -> 0
A41: =ceiling(sum(J41:BF138)-sum(J41:BF41),1) -> 987782 | B41: =ceiling(sum(J41:BF41),1) -> 345 | C41: =sum(E41:H41) -> 344.35 | D41: 45444 | E41: =sumif($J$19:BF40,E$19,$J41:BF41) -> 0 | F41: =sumif($J$19:BG40,F$19,$J41:BG41) -> 344.35 | G41: =sumif($J$19:BH40,G$19,$J41:BH41) -> 0 | H41: =sumif($J$19:BI40,H$19,$J41:BI41) -> 0 | I41: =if(D41=DATE(year(today()),month(today()),1),"Current",if(D41>DATE(year(today()),month(today()),1), "Future","Past")) -> Past | V41: =V$5 -> 344.35 | AE41: =if(and($D41>AE$7,$D41<AE$8),AE$5,0) -> 0 | AF41: =if(and($D41>AF$7,$D41<AF$8),AF$5,0) -> 0 | AG41: =if(and($D41>AG$7,$D41<AG$8),AG$5,0) -> 0 | AH41: =if(and($D41>AH$7,$D41<AH$8),AH$5,0) -> 0 | AI41: =if(and($D41>AI$7,$D41<AI$8),AI$5,0) -> 0 | AJ41: =if(and($D41>AJ$7,$D41<AJ$8),AJ$5,0) -> 0 | AK41: =if(and($D41>AK$7,$D41<AK$8),AK$5,0) -> 0 | AL41: =if(and($D41>AL$7,$D41<AL$8),AL$5,0) -> 0 | ... BF41: =if(and($D41>BF$7,$D41<BF$8),BF$5,0) -> 0
A42: =ceiling(sum(J42:BF139)-sum(J42:BF42),1) -> 981960 | B42: =ceiling(sum(J42:BF42),1) -> 5822 | C42: =sum(E42:H42) -> 5821.98 | D42: 45474 | E42: =sumif($J$19:BF41,E$19,$J42:BF42) -> 0 | F42: =sumif($J$19:BG41,F$19,$J42:BG42) -> 5821.98 | G42: =sumif($J$19:BH41,G$19,$J42:BH42) -> 0 | H42: =sumif($J$19:BI41,H$19,$J42:BI42) -> 0 | I42: =if(D42=DATE(year(today()),month(today()),1),"Current",if(D42>DATE(year(today()),month(today()),1), "Future","Past")) -> Past | K42: =K$5 -> 5477.63 | V42: =V$5 -> 344.35 | AE42: =if(and($D42>AE$7,$D42<AE$8),AE$5,0) -> 0 | AF42: =if(and($D42>AF$7,$D42<AF$8),AF$5,0) -> 0 | AG42: =if(and($D42>AG$7,$D42<AG$8),AG$5,0) -> 0 | AH42: =if(and($D42>AH$7,$D42<AH$8),AH$5,0) -> 0 | AI42: =if(and($D42>AI$7,$D42<AI$8),AI$5,0) -> 0 | AJ42: =if(and($D42>AJ$7,$D42<AJ$8),AJ$5,0) -> 0 | AK42: =if(and($D42>AK$7,$D42<AK$8),AK$5,0) -> 0 | AL42: =if(and($D42>AL$7,$D42<AL$8),AL$5,0) -> 0 | ... BF42: =if(and($D42>BF$7,$D42<BF$8),BF$5,0) -> 0
A43: =ceiling(sum(J43:BF140)-sum(J43:BF43),1) -> 976138 | B43: =ceiling(sum(J43:BF43),1) -> 5822 | C43: =sum(E43:H43) -> 5821.98 | D43: 45505 | E43: =sumif($J$19:BF42,E$19,$J43:BF43) -> 0 | F43: =sumif($J$19:BG42,F$19,$J43:BG43) -> 5821.98 | G43: =sumif($J$19:BH42,G$19,$J43:BH43) -> 0 | H43: =sumif($J$19:BI42,H$19,$J43:BI43) -> 0 | I43: =if(D43=DATE(year(today()),month(today()),1),"Current",if(D43>DATE(year(today()),month(today()),1), "Future","Past")) -> Past | K43: =K$5 -> 5477.63 | V43: =V$5 -> 344.35 | AE43: =if(and($D43>AE$7,$D43<AE$8),AE$5,0) -> 0 | AF43: =if(and($D43>AF$7,$D43<AF$8),AF$5,0) -> 0 | AG43: =if(and($D43>AG$7,$D43<AG$8),AG$5,0) -> 0 | AH43: =if(and($D43>AH$7,$D43<AH$8),AH$5,0) -> 0 | AI43: =if(and($D43>AI$7,$D43<AI$8),AI$5,0) -> 0 | AJ43: =if(and($D43>AJ$7,$D43<AJ$8),AJ$5,0) -> 0 | AK43: =if(and($D43>AK$7,$D43<AK$8),AK$5,0) -> 0 | AL43: =if(and($D43>AL$7,$D43<AL$8),AL$5,0) -> 0 | ... BF43: =if(and($D43>BF$7,$D43<BF$8),BF$5,0) -> 0
